Workbook

Sheet Model
A1: Line | B1: 2028 target | C1: 2032 target | D1: % of revenue 2028 | E1: % of revenue 2032 | F1: How the number is derived
A3: Volume
A4: Visits per day | B4: =Assumptions!$B$3*Assumptions!$B$5 | C4: =Assumptions!$B$3*Assumptions!$B$4 | F4: 2032: 579,000 (operator: Psychology Today traffic, Semrush via Perplexity). 2028: 12% of 2032 (operator).
A5: Visits per year | B5: =B4*Assumptions!$B$15 | C5: =C4*Assumptions!$B$15 | F5: Visits per day x 365
A6: Paying customers | B6: =B4/Assumptions!$B$7 | C6: =C4/Assumptions!$B$7 | F6: Visits per day / 3% (operator: 3% of paying customers visit each day)
A7: Visits per paying customer per year | B7: =Assumptions!$B$7*Assumptions!$B$15 | C7: =Assumptions!$B$7*Assumptions!$B$15 | F7: 3% x 365 days
A8: Average concurrent sessions | B8: =B4*Assumptions!$B$14/86400 | C8: =C4*Assumptions!$B$14/86400 | F8: Visits per day x 649 s (10 min 49 s, operator) / 86,400 s per day
A9: Peak concurrent sessions | B9: =B8*Assumptions!$B$33 | C9: =C8*Assumptions!$B$33 | F9: Average x 3 peak factor (my assumption)
A11: Revenue
A12: Annual plan | B12: =C12*Assumptions!$B$6 | C12: =C6*Assumptions!$B$8*Assumptions!$B$9 | D12: =IF(B15=0,0,B12/B15) | E12: =IF(C15=0,0,C12/C15) | F12: 2032: Paying customers x 30% x $60 per year (operator). 2028: 5% of the 2032 figure (operator)
A13: Monthly plan | B13: =C13*Assumptions!$B$6 | C13: =C6*Assumptions!$B$10*Assumptions!$B$11*12 | D13: =IF(B15=0,0,B13/B15) | E13: =IF(C15=0,0,C13/C15) | F13: 2032: Paying customers x 10% x $10 per month x 12 (operator; assumes a full year). 2028: 5% of the 2032 figure (operator)
A14: Single Use | B14: =C14*Assumptions!$B$6 | C14: =C6*Assumptions!$B$12*Assumptions!$B$13*C7 | D14: =IF(B15=0,0,B14/B15) | E14: =IF(C15=0,0,C14/C15) | F14: 2032: Paying customers x 60% x $2 per visit x 10.95 visits per year. 2028: 5% of the 2032 figure (operator)
A15: Anticipated revenue per year | B15: =B12+B13+B14 | C15: =C12+C13+C14 | D15: =IF(B15=0,0,B15/B15) | E15: =IF(C15=0,0,C15/C15) | F15: Sum of the three plans
A17: AI
A18: Gemini 2.5 Flash classifier cost per visit | B18: =Assumptions!$B$20*((Assumptions!$B$21/Assumptions!$B$22+Assumptions!$B$23)*Assumptions!$B$25+Assumptions!$B$24*Assumptions!$B$26)/1000000*Assumptions!$B$18*Assumptions!$B$19 | C18: =Assumptions!$B$20*((Assumptions!$B$21/Assumptions!$B$22+Assumptions!$B$23)*Assumptions!$B$25+Assumptions!$B$24*Assumptions!$B$26)/1000000*Assumptions!$B$18*Assumptions!$B$19 | F18: 4 calls (mine) x [(51,822 prompt chars measured / 4 + 500) input tokens x $0.30/M + 1,500 output tokens x $2.50/M] x 3 usage x 3 cost (operator)
A19: Claude Opus 5 cost per visit | B19: =Assumptions!$B$27*(Assumptions!$B$28*Assumptions!$B$30+Assumptions!$B$29*Assumptions!$B$31)/1000000*Assumptions!$B$18*Assumptions!$B$19 | C19: =Assumptions!$B$27*(Assumptions!$B$28*Assumptions!$B$30+Assumptions!$B$29*Assumptions!$B$31)/1000000*Assumptions!$B$18*Assumptions!$B$19 | F19: 0.10 calls (mine) x (4,000 input tokens x $5/M + 250 output tokens x $25/M) x 3 x 3
A20: Cost of all AI (recurring) | B20: =(B18+B19)*B5 | C20: =(C18+C19)*C5 | D20: =IF(B15=0,0,B20/B15) | E20: =IF(C15=0,0,C20/C15) | F20: Cost per visit x visits per year
A22: Hosting on Azure VMs
A23: App VMs (count) | B23: =ROUNDUP(B9/Assumptions!$B$34,0) | C23: =ROUNDUP(C9/Assumptions!$B$34,0) | F23: Peak sessions / 250 sessions per VM (mine), rounded up
A24: Compute | B24: =(B23*Assumptions!$B$35+Assumptions!$B$36*Assumptions!$B$37)*Assumptions!$B$16*12 | C24: =(C23*Assumptions!$B$35+Assumptions!$B$36*Assumptions!$B$37)*Assumptions!$B$16*12 | D24: =IF(B15=0,0,B24/B15) | E24: =IF(C15=0,0,C24/C15) | F24: (App VMs x $0.192/h D4s v5 + 6 DB VMs (mine) x $0.384/h D8s v5) x 730 h x 12; Azure list prices
A25: Data on disk (TiB, all copies) | B25: =B4*Assumptions!$B$15/12*Assumptions!$B$40*Assumptions!$B$39*Assumptions!$B$41/1024/1024/1024 | C25: =C4*Assumptions!$B$15/12*Assumptions!$B$40*Assumptions!$B$39*Assumptions!$B$41/1024/1024/1024 | F25: Visits over 12 months retained x 70 KB per visit x 3 copies (all mine)
A26: Storage | B26: =(ROUNDUP(B25,0)*Assumptions!$B$42+(B23+Assumptions!$B$36)*Assumptions!$B$38)*12 | C26: =(ROUNDUP(C25,0)*Assumptions!$B$42+(C23+Assumptions!$B$36)*Assumptions!$B$38)*12 | D26: =IF(B15=0,0,B26/B15) | E26: =IF(C15=0,0,C26/C15) | F26: (TiB rounded up x $135.17/month P30 disk + every VM x $19.71/month P10 OS disk) x 12; Azure list prices
A27: Network egress | B27: =B5*Assumptions!$B$43/1024*Assumptions!$B$44 | C27: =C5*Assumptions!$B$43/1024*Assumptions!$B$44 | D27: =IF(B15=0,0,B27/B15) | E27: =IF(C15=0,0,C27/C15) | F27: Visits per year x 3 MB per visit (mine) x $0.065 per GB (Azure tiers $0.08 to $0.04)
A28: Data pipelines (6) | B28: =Assumptions!$B$46*12 | C28: =Assumptions!$B$46*12 | D28: =IF(B15=0,0,B28/B15) | E28: =IF(C15=0,0,C28/C15) | F28: $50 per month for all 6 (operator) x 12
A29: Cost of all hosting (recurring) | B29: =B24+B26+B27+B28 | C29: =C24+C26+C27+C28 | D29: =IF(B15=0,0,B29/B15) | E29: =IF(C15=0,0,C29/C15) | F29: Compute + storage + egress + pipelines
A31: One-time sunk costs (counted once, in 2028)
A32: Sunk: AI vendors | B32: =SUMIF('Sunk Costs'!$C$3:$C$18,"AI",'Sunk Costs'!$B$3:$B$18) | C32: 0 | D32: =IF(B15=0,0,B32/B15) | E32: =IF(C15=0,0,C32/C15) | F32: Sunk Costs sheet, Bucket = AI
A33: Sunk: hosting vendors | B33: =SUMIF('Sunk Costs'!$C$3:$C$18,"Hosting",'Sunk Costs'!$B$3:$B$18) | C33: 0 | D33: =IF(B15=0,0,B33/B15) | E33: =IF(C15=0,0,C33/C15) | F33: Sunk Costs sheet, Bucket = Hosting
A34: Sunk: labor (deferred salary + equipment) | B34: =SUMIF('Sunk Costs'!$C$3:$C$18,"Labor",'Sunk Costs'!$B$3:$B$18) | C34: 0 | D34: =IF(B15=0,0,B34/B15) | E34: =IF(C15=0,0,C34/C15) | F34: Sunk Costs sheet, Bucket = Labor
A36: Business case (three buckets)
A37: AI | B37: =B20+B32 | C37: =C20+C32 | D37: =IF(B15=0,0,B37/B15) | E37: =IF(C15=0,0,C37/C15) | F37: Cost of all AI + AI sunk costs (2028 only)
A38: Hosting | B38: =B29+B33 | C38: =C29+C33 | D38: =IF(B15=0,0,B38/B15) | E38: =IF(C15=0,0,C38/C15) | F38: Cost of all hosting + hosting sunk costs (2028 only)
A39: Labor | B39: =Assumptions!$B$47*12*(1+Assumptions!$B$48)^0+B34 | C39: =Assumptions!$B$47*12*(1+Assumptions!$B$48)^4+C34 | D39: =IF(B15=0,0,B39/B15) | E39: =IF(C15=0,0,C39/C15) | F39: $80,000 per month x 12 in 2028, grown 15% a year compounded (2032 = x 1.15^4) (operator) + labor sunk costs (2028 only)
A40: Total of all costs | B40: =B37+B38+B39 | C40: =C37+C38+C39 | D40: =IF(B15=0,0,B40/B15) | E40: =IF(C15=0,0,C40/C15) | F40: AI + Hosting + Labor
A41: Operating profit | B41: =B15-B40 | C41: =C15-C40 | D41: =IF(B15=0,0,B41/B15) | E41: =IF(C15=0,0,C41/C15) | F41: Revenue - total of all costs
A43: Per paying customer, per year
A44: Revenue per paying customer | B44: =B15/B6 | C44: =C15/C6 | F44: Revenue / paying customers
A45: Cost per paying customer | B45: =B40/B6 | C45: =C40/C6 | F45: Total of all costs / paying customers
A46: Margin per paying customer | B46: =B41/B6 | C46: =C41/C6 | F46: Operating profit / paying customers
A47: Operating Margins (Non-GAAP) | B47: =IF(B15=0,0,B41/B15) | C47: =IF(C15=0,0,C41/C15) | F47: Operating profit / revenue
...

Sheet Assumptions
A1: Item | B1: Value | C1: Unit | D1: Source
A2: Traffic and revenue
A3: Visits per day at the 2032 target | B3: 579000 | C3: visits | D3: Operator (Psychology Today, Semrush via Perplexity)
A4: 2032 target: share of the 579,000 visits per day | B4: 1 | D4: Operator
A5: 2028 target: share of the 579,000 visits per day (drives 2028 costs) | B5: 0.12 | D5: Operator
A6: 2028 target: share of 2032 revenue | B6: 0.05 | D6: Operator
A7: Share of customers who visit per day | B7: 0.03 | D7: Operator
A8: Customers on Annual plan | B8: 0.3 | D8: Operator
A9: Annual plan price | B9: 60 | C9: $/year | D9: Operator
A10: Customers on Monthly plan | B10: 0.1 | D10: Operator
A11: Monthly plan price | B11: 10 | C11: $/month | D11: Operator
A12: Customers on Single Use | B12: 0.6 | D12: Operator
A13: Single Use price | B13: 2 | C13: $/visit | D13: Operator
A14: Average visit duration | B14: 649 | C14: seconds (10 min 49 s) | D14: Operator (Psychology Today, Semrush via Perplexity)
A15: Days per year | B15: 365 | C15: days
A16: Hours per month | B16: 730 | C16: hours | D16: Azure billing convention
A17: AI model utilization
A18: AI usage multiplier over today, per session | B18: 3 | C18: x | D18: Operator
A19: AI cost multiplier (applied on top of the usage multiplier) | B19: 3 | C19: x | D19: Operator
A20: Classifier calls per session today (one per user turn) | B20: 4 | C20: calls | D20: ASSUMPTION - not measured; please confirm
A21: Classifier system prompt size | B21: 51822 | C21: characters | D21: Measured from sharedServices/Code/UtteranceManager/utterance_manager.py
A22: Characters per token | B22: 4 | C22: chars | D22: ASSUMPTION - not measured; please confirm (common rule of thumb)
A23: Classifier per-turn message (dialogue window + state) | B23: 500 | C23: tokens | D23: ASSUMPTION - not measured; please confirm
A24: Classifier output per call, incl. Gemini thinking tokens | B24: 1500 | C24: tokens | D24: ASSUMPTION - not measured; please confirm
A25: Gemini 2.5 Flash input price | B25: 0.3 | C25: $/1M tokens | D25: ai.google.dev/gemini-api/docs/pricing, paid tier, fetched 2026-09-30
A26: Gemini 2.5 Flash output price (incl. thinking) | B26: 2.5 | C26: $/1M tokens | D26: ai.google.dev/gemini-api/docs/pricing, paid tier, fetched 2026-09-30
A27: Claude Opus 5 calls per session today (manufacture path, 'rare' per code) | B27: 0.1 | C27: calls | D27: ASSUMPTION - not measured; please confirm
A28: Opus input per call (prompt + dialogue + state + tool contracts) | B28: 4000 | C28: tokens | D28: ASSUMPTION - not measured; please confirm (system prompt alone measured at 1,569 chars)
A29: Opus output per call | B29: 250 | C29: tokens | D29: ASSUMPTION - not measured; please confirm (prompt caps at 150 words)
... A31: Claude Opus 5 output price | B31: 25 | C31: $/1M tokens | D31: docs.claude.com/en/docs/about-claude/pricing, fetched 2026-09-30
A32: Hosting on Azure VMs
A33: Peak-to-average concurrency | B33: 3 | C33: x | D33: ASSUMPTION - not measured; please confirm
A34: Concurrent sessions one app VM carries | B34: 250 | C34: sessions | D34: ASSUMPTION - not measured; please confirm
A35: App VM: Standard_D4s_v5 (4 vCPU, 16 GB) | B35: 0.192 | C35: $/hour | D35: Azure Retail Prices API (prices.azure.com), East US, Linux pay-as-you-go, fetched 2026-09-30
A36: Database VMs (MongoDB replica sets, self-hosted) | B36: 6 | C36: VMs | D36: ASSUMPTION - not measured; please confirm (2 shards x 3-node replica set)
A37: DB VM: Standard_D8s_v5 (8 vCPU, 32 GB) | B37: 0.384 | C37: $/hour | D37: Azure Retail Prices API (prices.azure.com), East US, Linux pay-as-you-go, fetched 2026-09-30
A38: OS disk per VM: Premium SSD P10 (128 GB) | B38: 19.71 | C38: $/month | D38: Azure Retail Prices API (prices.azure.com), East US, Linux pay-as-you-go, fetched 2026-09-30
A39: Data retained per session (session doc + logs) | B39: 70 | C39: KB | D39: ASSUMPTION - not measured; please confirm
A40: Retention | B40: 12 | C40: months | D40: ASSUMPTION - not measured; please confirm
A41: Database copies (replica set) | B41: 3 | C41: copies | D41: ASSUMPTION - not measured; please confirm
...

Sheet Sunk Costs
A1: Sunk Costs: realized and deferred, as of 9/30/2026
A2: Vendor | B2: Accrued Cost per Vendor | C2: Bucket
A3: Anthropic | B3: 1333.02 | C3: AI
A4: Best Buy | B4: 99.97 | C4: Labor
A5: CloudFlair | B5: 380 | C5: Hosting
A6: Deep Seek | B6: 10 | C6: AI
A7: Git Hub | B7: 70 | C7: Hosting
A8: Hugging Face | B8: 183.61 | C8: Hosting
A9: Mcafee subsription | B9: 119.99 | C9: Labor
A10: Mircosoft | B10: 1457.8 | C10: Hosting
A11: Mongo | B11: 4879.61 | C11: Hosting
A12: Office Depot | B12: 17.52 | C12: Labor
A13: Open AI | B13: 1126 | C13: AI
A14: Perplexity | B14: 50 | C14: AI
... A16: Twillio | B16: 20 | C16: Hosting
A17: Sunk Cost | B17: =SUM(B3:B16)
A18: Defered sallary | B18: 147000 | C18: Labor
A19: Total cost to date | B19: =B17+B18
A21: Source: Operator, Sunk Costs slide as of 9/30/2026. Vendor names as given. Bucket assignments are mine (change any of them and the Model recalculates).
